Workbook

Sheet 00 Raw Data
A1: 00. RAW DATA – SUZLON ENERGY LIMITED (FY22–FY26)
A2: All amounts in ₹ Crore unless otherwise stated. Financial figures are from audited standalone Ind AS financial statements. FY24 uses the restated comparative disclosed in the FY25 Annual Report (Ind AS 103 business-combination restatement).
A4: Statement | B4: Raw-data line item | C4: FY22 | D4: FY23 | E4: FY24 | F4: FY25 | G4: FY26 | H4: Source / Page
A5: Income Statement | B5: Revenue from operations | C5: 3975.41 | D5: 3538.14 | E5: 5834.35 | F5: 10161.6 | G5: 15053.58 | H5: FY22 AR p.110; FY23 AR p.207; FY24 restated in FY25 AR p.256; FY25 comparative in FY26 AR p.282; FY26 AR p.282
A6: Income Statement | B6: Other operating income | C6: 64.63 | D6: 52.3 | E6: 29.81 | F6: 36.12 | G6: 37.95 | H6: Same audited P&L pages as above
A7: Income Statement | B7: Finance income | C7: 63.02 | D7: 192.22 | E7: 47.37 | F7: 102.31 | G7: 154.13 | H7: Same audited P&L pages as above
A8: Income Statement | B8: Cost of raw materials, components and services consumed | C8: 3084.33 | D8: 2662.97 | E8: 3767.73 | F8: 6986.89 | G8: 10590.21 | H8: Same audited P&L pages as above
A9: Income Statement | B9: Purchase of stock-in-trade | C9: 0 | D9: 0 | E9: 0 | F9: 0 | G9: 0 | H9: Same audited P&L pages as above
A10: Income Statement | B10: Changes in inventories of finished goods, semi-finished goods and WIP | C10: 9.67 | D10: 77.53 | E10: -32.09 | F10: -269.17 | G10: -482.72 | H10: Same audited P&L pages as above
A11: Income Statement | B11: Employee benefits expense | C11: 225.62 | D11: 252.51 | E11: 585.75 | F11: 791.75 | G11: 767.95 | H11: Same audited P&L pages as above
A12: Income Statement | B12: Finance costs | C12: 777.08 | D12: 441.56 | E12: 144.43 | F12: 228.86 | G12: 417.74 | H12: Same audited P&L pages as above
A13: Income Statement | B13: Depreciation & amortisation expense | C13: 185.13 | D13: 190.04 | E13: 141.53 | F13: 166.85 | G13: 189.65 | H13: Same audited P&L pages as above
A14: Income Statement | B14: Other expenses | C14: 651.02 | D14: 537.37 | E14: 631.86 | F14: 1023.99 | G14: 1394.28 | H14: Same audited P&L pages as above
A15: Income Statement | B15: Exceptional items (reported sign) | C15: 82.87 | D15: -2542.08 | E15: -50.85 | F15: -102.86 | G15: -1178.4 | H15: Same audited P&L pages as above; negative amount represents exceptional gain under the P&L presentation
A16: Income Statement | B16: Total income tax expense / (credit) | C16: 0 | D16: 0 | E16: 0 | F16: -631 | G16: -564.06 | H16: Same audited P&L pages as above; tax credit shown as negative expense
... A58: Balance Sheet | B58: Contract liabilities | C58: 353.99 | D58: 386.66 | E58: 280.48 | F58: 1680.03 | G58: 1777.39 | H58: FY22 AR p.111; FY23 AR p.206; FY24 restated in FY25 AR p.254; FY25/FY26 comparative/current in FY26 AR p.280

Sheet 01 Income Statement
A1: 01. 5-Year Income Statement – Suzlon Energy Limited (Standalone)
A2: Audited standalone Ind AS financial statements; FY24 is the restated comparative in the FY25 Annual Report.
A4: Line item | B4: FY22 | C4: FY23 | D4: FY24 | E4: FY25 | F4: FY26 | G4: YoY FY23 | H4: YoY FY24 | I4: YoY FY25 | J4: YoY FY26 | K4: 5-Year Trend
A5: Revenue from operations | B5: ='00 Raw Data'!C5 -> 3975.41 | C5: ='00 Raw Data'!D5 -> 3538.14 | D5: ='00 Raw Data'!E5 -> 5834.35 | E5: ='00 Raw Data'!F5 -> 10161.6 | F5: ='00 Raw Data'!G5 -> 15053.58 | G5: =IFERROR((C5-B5)/B5,"") -> -0.10999369 | H5: =IFERROR((D5-C5)/C5,"") -> 0.64898789 | I5: =IFERROR((E5-D5)/D5,"") -> 0.74168502 | J5: =IFERROR((F5-E5)/E5,"") -> 0.48141828 | K5: =IFERROR(F5/B5-1,"") -> 2.7866736
A6: Other operating income | B6: ='00 Raw Data'!C6 -> 64.63 | C6: ='00 Raw Data'!D6 -> 52.3 | D6: ='00 Raw Data'!E6 -> 29.81 | E6: ='00 Raw Data'!F6 -> 36.12 | F6: ='00 Raw Data'!G6 -> 37.95 | G6: =IFERROR((C6-B6)/B6,"") -> -0.19077828 | H6: =IFERROR((D6-C6)/C6,"") -> -0.43001912 | I6: =IFERROR((E6-D6)/D6,"") -> 0.21167393 | J6: =IFERROR((F6-E6)/E6,"") -> 0.050664452 | K6: =IFERROR(F6/B6-1,"") -> -0.41281139
A7: Finance income | B7: ='00 Raw Data'!C7 -> 63.02 | C7: ='00 Raw Data'!D7 -> 192.22 | D7: ='00 Raw Data'!E7 -> 47.37 | E7: ='00 Raw Data'!F7 -> 102.31 | F7: ='00 Raw Data'!G7 -> 154.13 | G7: =IFERROR((C7-B7)/B7,"") -> 2.0501428 | H7: =IFERROR((D7-C7)/C7,"") -> -0.75356363 | I7: =IFERROR((E7-D7)/D7,"") -> 1.1598058 | J7: =IFERROR((F7-E7)/E7,"") -> 0.50649985 | K7: =IFERROR(F7/B7-1,"") -> 1.4457315
A8: Total income | B8: =B5+B6+B7 -> 4103.06 | C8: =C5+C6+C7 -> 3782.66 | D8: =D5+D6+D7 -> 5911.53 | E8: =E5+E6+E7 -> 10300.03 | F8: =F5+F6+F7 -> 15245.66 | G8: =IFERROR((C8-B8)/B8,"") -> -0.078088061 | H8: =IFERROR((D8-C8)/C8,"") -> 0.56279708 | I8: =IFERROR((E8-D8)/D8,"") -> 0.74236281 | J8: =IFERROR((F8-E8)/E8,"") -> 0.48015685 | K8: =IFERROR(F8/B8-1,"") -> 2.7156805
A9: Cost of raw materials, components and services consumed | B9: ='00 Raw Data'!C8 -> 3084.33 | C9: ='00 Raw Data'!D8 -> 2662.97 | D9: ='00 Raw Data'!E8 -> 3767.73 | E9: ='00 Raw Data'!F8 -> 6986.89 | F9: ='00 Raw Data'!G8 -> 10590.21 | G9: =IFERROR((C9-B9)/B9,"") -> -0.13661314 | H9: =IFERROR((D9-C9)/C9,"") -> 0.4148601 | I9: =IFERROR((E9-D9)/D9,"") -> 0.85440305 | J9: =IFERROR((F9-E9)/E9,"") -> 0.51572588 | K9: =IFERROR(F9/B9-1,"") -> 2.4335528
A10: Purchase of stock-in-trade | B10: ='00 Raw Data'!C9 -> 0 | C10: ='00 Raw Data'!D9 -> 0 | D10: ='00 Raw Data'!E9 -> 0 | E10: ='00 Raw Data'!F9 -> 0 | F10: ='00 Raw Data'!G9 -> 0 | G10: =IFERROR((C10-B10)/B10,"") | H10: =IFERROR((D10-C10)/C10,"") | I10: =IFERROR((E10-D10)/D10,"") | J10: =IFERROR((F10-E10)/E10,"") | K10: =IFERROR(F10/B10-1,"")
A11: Changes in inventories of finished goods, semi-finished goods and WIP | B11: ='00 Raw Data'!C10 -> 9.67 | C11: ='00 Raw Data'!D10 -> 77.53 | D11: ='00 Raw Data'!E10 -> -32.09 | E11: ='00 Raw Data'!F10 -> -269.17 | F11: ='00 Raw Data'!G10 -> -482.72 | G11: =IFERROR((C11-B11)/B11,"") -> 7.0175801 | H11: =IFERROR((D11-C11)/C11,"") -> -1.4139043 | I11: =IFERROR((E11-D11)/D11,"") -> 7.3879713 | J11: =IFERROR((F11-E11)/E11,"") -> 0.79336479 | K11: =IFERROR(F11/B11-1,"") -> -50.919338
A12: Employee benefits expense | B12: ='00 Raw Data'!C11 -> 225.62 | C12: ='00 Raw Data'!D11 -> 252.51 | D12: ='00 Raw Data'!E11 -> 585.75 | E12: ='00 Raw Data'!F11 -> 791.75 | F12: ='00 Raw Data'!G11 -> 767.95 | G12: =IFERROR((C12-B12)/B12,"") -> 0.1191827 | H12: =IFERROR((D12-C12)/C12,"") -> 1.3197101 | I12: =IFERROR((E12-D12)/D12,"") -> 0.35168587 | J12: =IFERROR((F12-E12)/E12,"") -> -0.030059994 | K12: =IFERROR(F12/B12-1,"") -> 2.4037319
A13: Finance costs | B13: ='00 Raw Data'!C12 -> 777.08 | C13: ='00 Raw Data'!D12 -> 441.56 | D13: ='00 Raw Data'!E12 -> 144.43 | E13: ='00 Raw Data'!F12 -> 228.86 | F13: ='00 Raw Data'!G12 -> 417.74 | G13: =IFERROR((C13-B13)/B13,"") -> -0.43177022 | H13: =IFERROR((D13-C13)/C13,"") -> -0.67290968 | I13: =IFERROR((E13-D13)/D13,"") -> 0.58457384 | J13: =IFERROR((F13-E13)/E13,"") -> 0.82530805 | K13: =IFERROR(F13/B13-1,"") -> -0.46242343
A14: Depreciation & amortisation expense | B14: ='00 Raw Data'!C13 -> 185.13 | C14: ='00 Raw Data'!D13 -> 190.04 | D14: ='00 Raw Data'!E13 -> 141.53 | E14: ='00 Raw Data'!F13 -> 166.85 | F14: ='00 Raw Data'!G13 -> 189.65 | G14: =IFERROR((C14-B14)/B14,"") -> 0.026521904 | H14: =IFERROR((D14-C14)/C14,"") -> -0.25526205 | I14: =IFERROR((E14-D14)/D14,"") -> 0.178902 | J14: =IFERROR((F14-E14)/E14,"") -> 0.13664969 | K14: =IFERROR(F14/B14-1,"") -> 0.024415276
A15: Other expenses | B15: ='00 Raw Data'!C14 -> 651.02 | C15: ='00 Raw Data'!D14 -> 537.37 | D15: ='00 Raw Data'!E14 -> 631.86 | E15: ='00 Raw Data'!F14 -> 1023.99 | F15: ='00 Raw Data'!G14 -> 1394.28 | G15: =IFERROR((C15-B15)/B15,"") -> -0.17457221 | H15: =IFERROR((D15-C15)/C15,"") -> 0.17583788 | I15: =IFERROR((E15-D15)/D15,"") -> 0.62059633 | J15: =IFERROR((F15-E15)/E15,"") -> 0.36161486 | K15: =IFERROR(F15/B15-1,"") -> 1.1416854
A16: Total expenses | B16: =SUM(B9:B15) -> 4932.85 | C16: =SUM(C9:C15) -> 4161.98 | D16: =SUM(D9:D15) -> 5239.21 | E16: =SUM(E9:E15) -> 8929.17 | F16: =SUM(F9:F15) -> 12877.11 | G16: =IFERROR((C16-B16)/B16,"") -> -0.15627274 | H16: =IFERROR((D16-C16)/C16,"") -> 0.25882633 | I16: =IFERROR((E16-D16)/D16,"") -> 0.70429702 | J16: =IFERROR((F16-E16)/E16,"") -> 0.44213964 | K16: =IFERROR(F16/B16-1,"") -> 1.6104808
A17: EBITDA / Operating profit before D&A | B17: =B5+B6-B9-B10-B11-B12-B15 -> 69.4 | C17: =C5+C6-C9-C10-C11-C12-C15 -> 60.06 | D17: =D5+D6-D9-D10-D11-D12-D15 -> 910.91 | E17: =E5+E6-E9-E10-E11-E12-E15 -> 1664.26 | F17: =F5+F6-F9-F10-F11-F12-F15 -> 2821.81 | G17: =IFERROR((C17-B17)/B17,"") -> -0.13458213 | H17: =IFERROR((D17-C17)/C17,"") -> 14.166667 | I17: =IFERROR((E17-D17)/D17,"") -> 0.82703011 | J17: =IFERROR((F17-E17)/E17,"") -> 0.69553435 | K17: =IFERROR(F17/B17-1,"") -> 39.660086
A18: EBIT / Operating profit | B18: =B17-B14 -> -115.73 | C18: =C17-C14 -> -129.98 | D18: =D17-D14 -> 769.38 | E18: =E17-E14 -> 1497.41 | F18: =F17-F14 -> 2632.16 | G18: =IFERROR((C18-B18)/B18,"") -> 0.12313143 | H18: =IFERROR((D18-C18)/C18,"") -> -6.9192183 | I18: =IFERROR((E18-D18)/D18,"") -> 0.94625543 | J18: =IFERROR((F18-E18)/E18,"") -> 0.75780848 | K18: =IFERROR(F18/B18-1,"") -> -23.743973
A19: Profit before exceptional items & tax | B19: =B18+B7-B13 -> -829.79 | C19: =C18+C7-C13 -> -379.32 | D19: =D18+D7-D13 -> 672.32 | E19: =E18+E7-E13 -> 1370.86 | F19: =F18+F7-F13 -> 2368.55 | G19: =IFERROR((C19-B19)/B19,"") -> -0.54287229 | H19: =IFERROR((D19-C19)/C19,"") -> -2.7724349 | I19: =IFERROR((E19-D19)/D19,"") -> 1.0389993 | J19: =IFERROR((F19-E19)/E19,"") -> 0.72778402 | K19: =IFERROR(F19/B19-1,"") -> -3.8543969
A20: Exceptional items | B20: ='00 Raw Data'!C15 -> 82.87 | C20: ='00 Raw Data'!D15 -> -2542.08 | D20: ='00 Raw Data'!E15 -> -50.85 | E20: ='00 Raw Data'!F15 -> -102.86 | F20: ='00 Raw Data'!G15 -> -1178.4 | G20: =IFERROR((C20-B20)/B20,"") -> -31.675516 | H20: =IFERROR((D20-C20)/C20,"") -> -0.9799967 | I20: =IFERROR((E20-D20)/D20,"") -> 1.0228122 | J20: =IFERROR((F20-E20)/E20,"") -> 10.456348 | K20: =IFERROR(F20/B20-1,"") -> -15.219862
A21: Profit / (loss) before tax | B21: =B19-B20 -> -912.66 | C21: =C19-C20 -> 2162.76 | D21: =D19-D20 -> 723.17 | E21: =E19-E20 -> 1473.72 | F21: =F19-F20 -> 3546.95 | G21: =IFERROR((C21-B21)/B21,"") -> -3.3697324 | H21: =IFERROR((D21-C21)/C21,"") -> -0.66562633 | I21: =IFERROR((E21-D21)/D21,"") -> 1.0378611 | J21: =IFERROR((F21-E21)/E21,"") -> 1.4068005 | K21: =IFERROR(F21/B21-1,"") -> -4.886387
A22: Total tax expense / (credit) | B22: ='00 Raw Data'!C16 -> 0 | C22: ='00 Raw Data'!D16 -> 0 | D22: ='00 Raw Data'!E16 -> 0 | E22: ='00 Raw Data'!F16 -> -631 | F22: ='00 Raw Data'!G16 -> -564.06 | G22: =IFERROR((C22-B22)/B22,"") | H22: =IFERROR((D22-C22)/C22,"") | I22: =IFERROR((E22-D22)/D22,"") | J22: =IFERROR((F22-E22)/E22,"") -> -0.10608558 | K22: =IFERROR(F22/B22-1,"")
A23: Profit / (loss) for the year (PAT) | B23: =B21-B22 -> -912.66 | C23: =C21-C22 -> 2162.76 | D23: =D21-D22 -> 723.17 | E23: =E21-E22 -> 2104.72 | F23: =F21-F22 -> 4111.01 | G23: =IFERROR((C23-B23)/B23,"") -> -3.3697324 | H23: =IFERROR((D23-C23)/C23,"") -> -0.66562633 | I23: =IFERROR((E23-D23)/D23,"") -> 1.9104083 | J23: =IFERROR((F23-E23)/E23,"") -> 0.95323368 | K23: =IFERROR(F23/B23-1,"") -> -5.5044266
A24: Other comprehensive income / (loss), net of tax | B24: ='00 Raw Data'!C17 -> 1.67 | C24: ='00 Raw Data'!D17 -> -5.71 | D24: ='00 Raw Data'!E17 -> 3.43 | E24: ='00 Raw Data'!F17 -> 5.98 | F24: ='00 Raw Data'!G17 -> 1.34 | G24: =IFERROR((C24-B24)/B24,"") -> -4.4191617 | H24: =IFERROR((D24-C24)/C24,"") -> -1.6007005 | I24: =IFERROR((E24-D24)/D24,"") -> 0.74344023 | J24: =IFERROR((F24-E24)/E24,"") -> -0.77591973 | K24: =IFERROR(F24/B24-1,"") -> -0.19760479
A25: Total comprehensive income / (loss) | B25: =B23+B24 -> -910.99 | C25: =C23+C24 -> 2157.05 | D25: =D23+D24 -> 726.6 | E25: =E23+E24 -> 2110.7 | F25: =F23+F24 -> 4112.35 | G25: =IFERROR((C25-B25)/B25,"") -> -3.3678086 | H25: =IFERROR((D25-C25)/C25,"") -> -0.66315106 | I25: =IFERROR((E25-D25)/D25,"") -> 1.9048995 | J25: =IFERROR((F25-E25)/E25,"") -> 0.94833468 | K25: =IFERROR(F25/B25-1,"") -> -5.5141549

Sheet 02 Income Ratios
A1: 02. Income Statement Ratios – Suzlon Energy Limited
A2: Ratios are formula-driven from the audited standalone income statement.
A4: Ratio | B4: FY22 | C4: FY23 | D4: FY24 | E4: FY25 | F4: FY26 | G4: 5-Year Trend | H4: Interpretation / Analysis
A5: Revenue growth (YoY) | B5: ="" | C5: =IFERROR(('01 Income Statement'!C5-'01 Income Statement'!B5)/'01 Income Statement'!B5,"") -> -0.10999369 | D5: =IFERROR(('01 Income Statement'!D5-'01 Income Statement'!C5)/'01 Income Statement'!C5,"") -> 0.64898789 | E5: =IFERROR(('01 Income Statement'!E5-'01 Income Statement'!D5)/'01 Income Statement'!D5,"") -> 0.74168502 | F5: =IFERROR(('01 Income Statement'!F5-'01 Income Statement'!E5)/'01 Income Statement'!E5,"") -> 0.48141828 | G5: Strong acceleration; revenue scaled sharply in FY25–FY26. | H5: Strong acceleration; revenue scaled sharply in FY25–FY26.
A6: EBITDA margin | B6: =IFERROR('01 Income Statement'!B17/'01 Income Statement'!B5,"") -> 0.017457319 | C6: =IFERROR('01 Income Statement'!C17/'01 Income Statement'!C5,"") -> 0.016975021 | D6: =IFERROR('01 Income Statement'!D17/'01 Income Statement'!D5,"") -> 0.15612879 | E6: =IFERROR('01 Income Statement'!E17/'01 Income Statement'!E5,"") -> 0.16377933 | F6: =IFERROR('01 Income Statement'!F17/'01 Income Statement'!F5,"") -> 0.18745109 | G6: Operating margin improved materially from FY22 losses to >18% in FY26. | H6: Operating margin improved materially from FY22 losses to >18% in FY26.
A7: EBIT margin | B7: =IFERROR('01 Income Statement'!B18/'01 Income Statement'!B5,"") -> -0.029111463 | C7: =IFERROR('01 Income Statement'!C18/'01 Income Statement'!C5,"") -> -0.036736817 | D7: =IFERROR('01 Income Statement'!D18/'01 Income Statement'!D5,"") -> 0.13187073 | E7: =IFERROR('01 Income Statement'!E18/'01 Income Statement'!E5,"") -> 0.14735967 | F7: =IFERROR('01 Income Statement'!F18/'01 Income Statement'!F5,"") -> 0.17485276 | G7: EBIT margin recovered from negative FY22 to 17.5% in FY26. | H7: EBIT margin recovered from negative FY22 to 17.5% in FY26.
A8: PBT margin | B8: =IFERROR('01 Income Statement'!B21/'01 Income Statement'!B5,"") -> -0.22957632 | C8: =IFERROR('01 Income Statement'!C21/'01 Income Statement'!C5,"") -> 0.61127033 | D8: =IFERROR('01 Income Statement'!D21/'01 Income Statement'!D5,"") -> 0.1239504 | E8: =IFERROR('01 Income Statement'!E21/'01 Income Statement'!E5,"") -> 0.14502834 | F8: =IFERROR('01 Income Statement'!F21/'01 Income Statement'!F5,"") -> 0.23562169 | G8: PBT margin turned positive after FY22 and strengthened strongly by FY26. | H8: PBT margin turned positive after FY22 and strengthened strongly by FY26.
A9: PAT margin | B9: =IFERROR('01 Income Statement'!B23/'01 Income Statement'!B5,"") -> -0.22957632 | C9: =IFERROR('01 Income Statement'!C23/'01 Income Statement'!C5,"") -> 0.61127033 | D9: =IFERROR('01 Income Statement'!D23/'01 Income Statement'!D5,"") -> 0.1239504 | E9: =IFERROR('01 Income Statement'!E23/'01 Income Statement'!E5,"") -> 0.20712486 | F9: =IFERROR('01 Income Statement'!F23/'01 Income Statement'!F5,"") -> 0.27309185 | G9: PAT margin is volatile because of exceptional gains/losses and tax credits. | H9: PAT margin is volatile because of exceptional gains/losses and tax credits.
A10: Finance income / PBT before exceptional | B10: =IFERROR('01 Income Statement'!B7/'01 Income Statement'!B19,"") -> -0.075946926 | C10: =IFERROR('01 Income Statement'!C7/'01 Income Statement'!C19,"") -> -0.50674892 | D10: =IFERROR('01 Income Statement'!D7/'01 Income Statement'!D19,"") -> 0.07045752 | E10: =IFERROR('01 Income Statement'!E7/'01 Income Statement'!E19,"") -> 0.074631983 | F10: =IFERROR('01 Income Statement'!F7/'01 Income Statement'!F19,"") -> 0.065073568 | G10: Finance income is modest relative to operating earnings; FY23 was unusually high. | H10: Finance income is modest relative to operating earnings; FY23 was unusually high.
A11: Exceptional items / PBT | B11: =IFERROR('01 Income Statement'!B20/'01 Income Statement'!B21,"") -> -0.090800517 | C11: =IFERROR('01 Income Statement'!C20/'01 Income Statement'!C21,"") -> -1.175387 | D11: =IFERROR('01 Income Statement'!D20/'01 Income Statement'!D21,"") -> -0.070315417 | E11: =IFERROR('01 Income Statement'!E20/'01 Income Statement'!E21,"") -> -0.069796162 | F11: =IFERROR('01 Income Statement'!F20/'01 Income Statement'!F21,"") -> -0.3322291 | G11: Exceptional items materially distorted FY23, FY24, FY25 and FY26 PBT. | H11: Exceptional items materially distorted FY23, FY24, FY25 and FY26 PBT.
A12: Effective tax rate | B12: =IFERROR('01 Income Statement'!B22/'01 Income Statement'!B21,"") -> 0 | C12: =IFERROR('01 Income Statement'!C22/'01 Income Statement'!C21,"") -> 0 | D12: =IFERROR('01 Income Statement'!D22/'01 Income Statement'!D21,"") -> 0 | E12: =IFERROR('01 Income Statement'!E22/'01 Income Statement'!E21,"") -> -0.42816817 | F12: =IFERROR('01 Income Statement'!F22/'01 Income Statement'!F21,"") -> -0.15902677 | G12: Tax rate is unusual because FY25–FY26 tax is largely deferred-tax credit. | H12: Tax rate is unusual because FY25–FY26 tax is largely deferred-tax credit.
A13: Interest coverage (EBIT / finance cost) | B13: =IFERROR('01 Income Statement'!B18/'01 Income Statement'!B13,"") -> -0.14892933 | C13: =IFERROR('01 Income Statement'!C18/'01 Income Statement'!C13,"") -> -0.29436543 | D13: =IFERROR('01 Income Statement'!D18/'01 Income Statement'!D13,"") -> 5.3270096 | E13: =IFERROR('01 Income Statement'!E18/'01 Income Statement'!E13,"") -> 6.5429083 | F13: =IFERROR('01 Income Statement'!F18/'01 Income Statement'!F13,"") -> 6.3009527 | G13: Coverage improved from negative FY22 to a healthy level, though FY26 finance cost rose. | H13: Coverage improved from negative FY22 to a healthy level, though FY26 finance cost rose.
A14: Finance cost / Revenue | B14: =IFERROR('01 Income Statement'!B13/'01 Income Statement'!B5,"") -> 0.19547166 | C14: =IFERROR('01 Income Statement'!C13/'01 Income Statement'!C5,"") -> 0.12480004 | D14: =IFERROR('01 Income Statement'!D13/'01 Income Statement'!D5,"") -> 0.024755114 | E14: =IFERROR('01 Income Statement'!E13/'01 Income Statement'!E5,"") -> 0.022522044 | F14: =IFERROR('01 Income Statement'!F13/'01 Income Statement'!F5,"") -> 0.02775021 | G14: Finance-cost burden fell through FY24, then rose again in FY26. | H14: Finance-cost burden fell through FY24, then rose again in FY26.
A15: Operating expenses / Revenue | B15: =IFERROR(('01 Income Statement'!B16-'01 Income Statement'!B13)/'01 Income Statement'!B5,"") -> 1.0453689 | C15: =IFERROR(('01 Income Statement'!C16-'01 Income Statement'!C13)/'01 Income Statement'!C5,"") -> 1.0515186 | D15: =IFERROR(('01 Income Statement'!D16-'01 Income Statement'!D13)/'01 Income Statement'!D5,"") -> 0.87323866 | E15: =IFERROR(('01 Income Statement'!E16-'01 Income Statement'!E13)/'01 Income Statement'!E5,"") -> 0.85619489 | F15: =IFERROR(('01 Income Statement'!F16-'01 Income Statement'!F13)/'01 Income Statement'!F5,"") -> 0.82766824 | G15: Operating-cost intensity declined as scale and margins improved. | H15: Operating-cost intensity declined as scale and margins improved.
A16: D&A / Revenue | B16: =IFERROR('01 Income Statement'!B14/'01 Income Statement'!B5,"") -> 0.046568782 | C16: =IFERROR('01 Income Statement'!C14/'01 Income Statement'!C5,"") -> 0.053711837 | D16: =IFERROR('01 Income Statement'!D14/'01 Income Statement'!D5,"") -> 0.024258058 | E16: =IFERROR('01 Income Statement'!E14/'01 Income Statement'!E5,"") -> 0.016419658 | F16: =IFERROR('01 Income Statement'!F14/'01 Income Statement'!F5,"") -> 0.012598332 | G16: D&A intensity has remained relatively low versus revenue. | H16: D&A intensity has remained relatively low versus revenue.
A17: PAT growth (YoY) | B17: ="" | C17: =IFERROR(('01 Income Statement'!C23-'01 Income Statement'!B23)/'01 Income Statement'!B23,"") -> -3.3697324 | D17: =IFERROR(('01 Income Statement'!D23-'01 Income Statement'!C23)/'01 Income Statement'!C23,"") -> -0.66562633 | E17: =IFERROR(('01 Income Statement'!E23-'01 Income Statement'!D23)/'01 Income Statement'!D23,"") -> 1.9104083 | F17: =IFERROR(('01 Income Statement'!F23-'01 Income Statement'!E23)/'01 Income Statement'!E23,"") -> 0.95323368 | G17: PAT growth is highly distorted by exceptional items and tax credits. | H17: PAT growth is highly distorted by exceptional items and tax credits.

Sheet 03 Balance Sheet
A1: 03. 5-Year Balance Sheet – Suzlon Energy Limited (Standalone)
A2: FY24 uses the restated comparative disclosed in the FY25 Annual Report. Investment properties are included within the 'other non-current assets' bucket for structural comparability.
A4: Line item | B4: FY22 | C4: FY23 | D4: FY24 | E4: FY25 | F4: FY26 | G4: YoY FY23 | H4: YoY FY24 | I4: YoY FY25 | J4: YoY FY26 | K4: Analysis / Observation
A5: Property, plant & equipment | B5: ='00 Raw Data'!C22 -> 466.78 | C5: ='00 Raw Data'!D22 -> 425.07 | D5: ='00 Raw Data'!E22 -> 554.87 | E5: ='00 Raw Data'!F22 -> 579.31 | F5: ='00 Raw Data'!G22 -> 758.81 | G5: =IFERROR((C5-B5)/B5,"") -> -0.08935687 | H5: =IFERROR((D5-C5)/C5,"") -> 0.30536147 | I5: =IFERROR((E5-D5)/D5,"") -> 0.044046353 | J5: =IFERROR((F5-E5)/E5,"") -> 0.30985137 | K5: =IFERROR(F5/B5-1,"") -> 0.62562663
A6: Right-of-use assets | B6: ='00 Raw Data'!C23 -> 58.96 | C6: ='00 Raw Data'!D23 -> 9.19 | D6: ='00 Raw Data'!E23 -> 35.62 | E6: ='00 Raw Data'!F23 -> 36.06 | F6: ='00 Raw Data'!G23 -> 293.96 | G6: =IFERROR((C6-B6)/B6,"") -> -0.84413161 | H6: =IFERROR((D6-C6)/C6,"") -> 2.8759521 | I6: =IFERROR((E6-D6)/D6,"") -> 0.012352611 | J6: =IFERROR((F6-E6)/E6,"") -> 7.1519689 | K6: =IFERROR(F6/B6-1,"") -> 3.9857531
A7: Capital work-in-progress | B7: ='00 Raw Data'!C24 -> 7.63 | C7: ='00 Raw Data'!D24 -> 0.87 | D7: ='00 Raw Data'!E24 -> 4.28 | E7: ='00 Raw Data'!F24 -> 59.59 | F7: ='00 Raw Data'!G24 -> 137.88 | G7: =IFERROR((C7-B7)/B7,"") -> -0.88597641 | H7: =IFERROR((D7-C7)/C7,"") -> 3.9195402 | I7: =IFERROR((E7-D7)/D7,"") -> 12.922897 | J7: =IFERROR((F7-E7)/E7,"") -> 1.313811 | K7: =IFERROR(F7/B7-1,"") -> 17.070773
A8: Intangible assets | B8: ='00 Raw Data'!C25 -> 124.7 | C8: ='00 Raw Data'!D25 -> 62.9 | D8: ='00 Raw Data'!E25 -> 55.35 | E8: ='00 Raw Data'!F25 -> 91.35 | F8: ='00 Raw Data'!G25 -> 155.33 | G8: =IFERROR((C8-B8)/B8,"") -> -0.49558941 | H8: =IFERROR((D8-C8)/C8,"") -> -0.1200318 | I8: =IFERROR((E8-D8)/D8,"") -> 0.6504065 | J8: =IFERROR((F8-E8)/E8,"") -> 0.70038314 | K8: =IFERROR(F8/B8-1,"") -> 0.24562951
A9: Intangible assets under development | B9: ='00 Raw Data'!C26 -> 4.42 | C9: ='00 Raw Data'!D26 -> 3.43 | D9: ='00 Raw Data'!E26 -> 3.51 | E9: ='00 Raw Data'!F26 -> 16.35 | F9: ='00 Raw Data'!G26 -> 13.57 | G9: =IFERROR((C9-B9)/B9,"") -> -0.2239819 | H9: =IFERROR((D9-C9)/C9,"") -> 0.023323615 | I9: =IFERROR((E9-D9)/D9,"") -> 3.6581197 | J9: =IFERROR((F9-E9)/E9,"") -> -0.17003058 | K9: =IFERROR(F9/B9-1,"") -> 2.0701357
A10: Non-current investments | B10: ='00 Raw Data'!C27 -> 1751.98 | C10: ='00 Raw Data'!D27 -> 1753.9 | D10: ='00 Raw Data'!E27 -> 370.25 | E10: ='00 Raw Data'!F27 -> 1277.7 | F10: ='00 Raw Data'!G27 -> 2123.28 | G10: =IFERROR((C10-B10)/B10,"") -> 0.0010959029 | H10: =IFERROR((D10-C10)/C10,"") -> -0.78889903 | I10: =IFERROR((E10-D10)/D10,"") -> 2.4509115 | J10: =IFERROR((F10-E10)/E10,"") -> 0.66179854 | K10: =IFERROR(F10/B10-1,"") -> 0.21193164
A11: Non-current loans | B11: ='00 Raw Data'!C28 -> 52.51 | C11: ='00 Raw Data'!D28 -> 1244.42 | D11: ='00 Raw Data'!E28 -> 95.07 | E11: ='00 Raw Data'!F28 -> 139.06 | F11: ='00 Raw Data'!G28 -> 525.64 | G11: =IFERROR((C11-B11)/B11,"") -> 22.698724 | H11: =IFERROR((D11-C11)/C11,"") -> -0.92360296 | I11: =IFERROR((E11-D11)/D11,"") -> 0.46271169 | J11: =IFERROR((F11-E11)/E11,"") -> 2.7799511 | K11: =IFERROR(F11/B11-1,"") -> 9.0102838
A12: Other non-current financial assets | B12: ='00 Raw Data'!C29 -> 228.67 | C12: ='00 Raw Data'!D29 -> 383.39 | D12: ='00 Raw Data'!E29 -> 871.82 | E12: ='00 Raw Data'!F29 -> 1062.67 | F12: ='00 Raw Data'!G29 -> 1397.21 | G12: =IFERROR((C12-B12)/B12,"") -> 0.67660821 | H12: =IFERROR((D12-C12)/C12,"") -> 1.2739769 | I12: =IFERROR((E12-D12)/D12,"") -> 0.21890987 | J12: =IFERROR((F12-E12)/E12,"") -> 0.31481081 | K12: =IFERROR(F12/B12-1,"") -> 5.1101587
A13: Deferred tax assets (net) | B13: ='00 Raw Data'!C30 -> 0 | C13: ='00 Raw Data'!D30 -> 0 | D13: ='00 Raw Data'!E30 -> 0 | E13: ='00 Raw Data'!F30 -> 638.05 | F13: ='00 Raw Data'!G30 -> 1202.11 | G13: =IFERROR((C13-B13)/B13,"") | H13: =IFERROR((D13-C13)/C13,"") | I13: =IFERROR((E13-D13)/D13,"") | J13: =IFERROR((F13-E13)/E13,"") -> 0.8840373 | K13: =IFERROR(F13/B13-1,"")
A14: Non-current tax assets | B14: ='00 Raw Data'!C31 -> 0 | C14: ='00 Raw Data'!D31 -> 0 | D14: ='00 Raw Data'!E31 -> 0 | E14: ='00 Raw Data'!F31 -> 0 | F14: ='00 Raw Data'!G31 -> 0 | G14: =IFERROR((C14-B14)/B14,"") | H14: =IFERROR((D14-C14)/C14,"") | I14: =IFERROR((E14-D14)/D14,"") | J14: =IFERROR((F14-E14)/E14,"") | K14: =IFERROR(F14/B14-1,"")
A15: Other non-current assets (incl. investment properties) | B15: ='00 Raw Data'!C32 -> 100.15 | C15: ='00 Raw Data'!D32 -> 100.52 | D15: ='00 Raw Data'!E32 -> 99.62 | E15: ='00 Raw Data'!F32 -> 88.29 | F15: ='00 Raw Data'!G32 -> 54.39 | G15: =IFERROR((C15-B15)/B15,"") -> 0.0036944583 | H15: =IFERROR((D15-C15)/C15,"") -> -0.0089534421 | I15: =IFERROR((E15-D15)/D15,"") -> -0.11373218 | J15: =IFERROR((F15-E15)/E15,"") -> -0.38396194 | K15: =IFERROR(F15/B15-1,"") -> -0.45691463
A16: Total non-current assets | B16: =SUM(B5:B15) -> 2795.8 | C16: =SUM(C5:C15) -> 3983.69 | D16: =SUM(D5:D15) -> 2090.39 | E16: =SUM(E5:E15) -> 3988.43 | F16: =SUM(F5:F15) -> 6662.18 | G16: =IFERROR((C16-B16)/B16,"") -> 0.42488375 | H16: =IFERROR((D16-C16)/C16,"") -> -0.47526288 | I16: =IFERROR((E16-D16)/D16,"") -> 0.90798368 | J16: =IFERROR((F16-E16)/E16,"") -> 0.67037656 | K16: =IFERROR(F16/B16-1,"") -> 1.3829244
A17: Inventories | B17: ='00 Raw Data'!C33 -> 1167.47 | C17: ='00 Raw Data'!D33 -> 760.42 | D17: ='00 Raw Data'!E33 -> 2053.52 | E17: ='00 Raw Data'!F33 -> 2857.11 | F17: ='00 Raw Data'!G33 -> 3557.49 | G17: =IFERROR((C17-B17)/B17,"") -> -0.34865992 | H17: =IFERROR((D17-C17)/C17,"") -> 1.7005076 | I17: =IFERROR((E17-D17)/D17,"") -> 0.39132319 | J17: =IFERROR((F17-E17)/E17,"") -> 0.24513582 | K17: =IFERROR(F17/B17-1,"") -> 2.0471789
A18: Current investments | B18: ='00 Raw Data'!C34 -> 0 | C18: ='00 Raw Data'!D34 -> 0 | D18: ='00 Raw Data'!E34 -> 8.35 | E18: ='00 Raw Data'!F34 -> 0 | F18: ='00 Raw Data'!G34 -> 213.89 | G18: =IFERROR((C18-B18)/B18,"") | H18: =IFERROR((D18-C18)/C18,"") | I18: =IFERROR((E18-D18)/D18,"") -> -1 | J18: =IFERROR((F18-E18)/E18,"") | K18: =IFERROR(F18/B18-1,"")
A19: Trade receivables | B19: ='00 Raw Data'!C35 -> 667.63 | C19: ='00 Raw Data'!D35 -> 546.32 | D19: ='00 Raw Data'!E35 -> 1658.56 | E19: ='00 Raw Data'!F35 -> 3682.9 | F19: ='00 Raw Data'!G35 -> 5741.95 | G19: =IFERROR((C19-B19)/B19,"") -> -0.18170244 | H19: =IFERROR((D19-C19)/C19,"") -> 2.0358764 | I19: =IFERROR((E19-D19)/D19,"") -> 1.2205407 | J19: =IFERROR((F19-E19)/E19,"") -> 0.55908387 | K19: =IFERROR(F19/B19-1,"") -> 7.6004973
A20: Cash & cash equivalents | B20: ='00 Raw Data'!C36 -> 350.75 | C20: ='00 Raw Data'!D36 -> 290.63 | D20: ='00 Raw Data'!E36 -> 184.89 | E20: ='00 Raw Data'!F36 -> 808.02 | F20: ='00 Raw Data'!G36 -> 297.67 | G20: =IFERROR((C20-B20)/B20,"") -> -0.17140413 | H20: =IFERROR((D20-C20)/C20,"") -> -0.3638303 | I20: =IFERROR((E20-D20)/D20,"") -> 3.3702742 | J20: =IFERROR((F20-E20)/E20,"") -> -0.63160565 | K20: =IFERROR(F20/B20-1,"") -> -0.15133286
A21: Bank balances other than cash & cash equivalents | B21: ='00 Raw Data'!C37 -> 59.27 | C21: ='00 Raw Data'!D37 -> 0 | D21: ='00 Raw Data'!E37 -> 177.27 | E21: ='00 Raw Data'!F37 -> 188.78 | F21: ='00 Raw Data'!G37 -> 575.27 | G21: =IFERROR((C21-B21)/B21,"") -> -1 | H21: =IFERROR((D21-C21)/C21,"") | I21: =IFERROR((E21-D21)/D21,"") -> 0.064929204 | J21: =IFERROR((F21-E21)/E21,"") -> 2.0473037 | K21: =IFERROR(F21/B21-1,"") -> 8.7059221
A22: Current loans | B22: ='00 Raw Data'!C38 -> 52.35 | C22: ='00 Raw Data'!D38 -> 0.61 | D22: ='00 Raw Data'!E38 -> 0.26 | E22: ='00 Raw Data'!F38 -> 0.27 | F22: ='00 Raw Data'!G38 -> 133.07 | G22: =IFERROR((C22-B22)/B22,"") -> -0.98834766 | H22: =IFERROR((D22-C22)/C22,"") -> -0.57377049 | I22: =IFERROR((E22-D22)/D22,"") -> 0.038461538 | J22: =IFERROR((F22-E22)/E22,"") -> 491.85185 | K22: =IFERROR(F22/B22-1,"") -> 1.5419293
A23: Other current financial assets | B23: ='00 Raw Data'!C39 -> 76.36 | C23: ='00 Raw Data'!D39 -> 75.5 | D23: ='00 Raw Data'!E39 -> 153.67 | E23: ='00 Raw Data'!F39 -> 185.63 | F23: ='00 Raw Data'!G39 -> 201.99 | G23: =IFERROR((C23-B23)/B23,"") -> -0.011262441 | H23: =IFERROR((D23-C23)/C23,"") -> 1.0353642 | I23: =IFERROR((E23-D23)/D23,"") -> 0.20797813 | J23: =IFERROR((F23-E23)/E23,"") -> 0.088132306 | K23: =IFERROR(F23/B23-1,"") -> 1.6452331
A24: Other current assets (incl. current tax assets) | B24: ='00 Raw Data'!C40 -> 410.09 | C24: ='00 Raw Data'!D40 -> 363.01 | D24: ='00 Raw Data'!E40 -> 430.14 | E24: ='00 Raw Data'!F40 -> 633.32 | F24: ='00 Raw Data'!G40 -> 701.27 | G24: =IFERROR((C24-B24)/B24,"") -> -0.11480407 | H24: =IFERROR((D24-C24)/C24,"") -> 0.18492604 | I24: =IFERROR((E24-D24)/D24,"") -> 0.47235784 | J24: =IFERROR((F24-E24)/E24,"") -> 0.10729173 | K24: =IFERROR(F24/B24-1,"") -> 0.71003926
A25: Assets held for sale | B25: ='00 Raw Data'!C41 -> 95.54 | C25: ='00 Raw Data'!D41 -> 27.81 | D25: ='00 Raw Data'!E41 -> 0 | E25: ='00 Raw Data'!F41 -> 0 | F25: ='00 Raw Data'!G41 -> 0 | G25: =IFERROR((C25-B25)/B25,"") -> -0.70891773 | H25: =IFERROR((D25-C25)/C25,"") -> -1 | I25: =IFERROR((E25-D25)/D25,"") | J25: =IFERROR((F25-E25)/E25,"") | K25: =IFERROR(F25/B25-1,"") -> -1
A26: Total current assets | B26: =SUM(B17:B25) -> 2879.46 | C26: =SUM(C17:C25) -> 2064.3 | D26: =SUM(D17:D25) -> 4666.66 | E26: =SUM(E17:E25) -> 8356.03 | F26: =SUM(F17:F25) -> 11422.6 | G26: =IFERROR((C26-B26)/B26,"") -> -0.28309475 | H26: =IFERROR((D26-C26)/C26,"") -> 1.2606501 | I26: =IFERROR((E26-D26)/D26,"") -> 0.79058042 | J26: =IFERROR((F26-E26)/E26,"") -> 0.36698887 | K26: =IFERROR(F26/B26-1,"") -> 2.9669244
A27: TOTAL ASSETS | B27: =B16+B26 -> 5675.26 | C27: =C16+C26 -> 6047.99 | D27: =D16+D26 -> 6757.05 | E27: =E16+E26 -> 12344.46 | F27: =F16+F26 -> 18084.78 | G27: =IFERROR((C27-B27)/B27,"") -> 0.065676286 | H27: =IFERROR((D27-C27)/C27,"") -> 0.11723895 | I27: =IFERROR((E27-D27)/D27,"") -> 0.82690079 | J27: =IFERROR((F27-E27)/E27,"") -> 0.46501184 | K27: =IFERROR(F27/B27-1,"") -> 2.1865994
A28: Equity share capital | B28: ='00 Raw Data'!C42 -> 1843.49 | C28: ='00 Raw Data'!D42 -> 2454.4 | D28: ='00 Raw Data'!E42 -> 2721.72 | E28: ='00 Raw Data'!F42 -> 2731.79 | F28: ='00 Raw Data'!G42 -> 2744.99 | G28: =IFERROR((C28-B28)/B28,"") -> 0.33138775 | H28: =IFERROR((D28-C28)/C28,"") -> 0.1089146 | I28: =IFERROR((E28-D28)/D28,"") -> 0.0036998663 | J28: =IFERROR((F28-E28)/E28,"") -> 0.0048319966 | K28: =IFERROR(F28/B28-1,"") -> 0.48901811
A29: Other equity | B29: ='00 Raw Data'!C43 -> -5735.58 | C29: ='00 Raw Data'!D43 -> -1035.01 | D29: ='00 Raw Data'!E43 -> 559.47 | E29: ='00 Raw Data'!F43 -> 2797.21 | F29: ='00 Raw Data'!G43 -> 7082.76 | G29: =IFERROR((C29-B29)/B29,"") -> -0.81954571 | H29: =IFERROR((D29-C29)/C29,"") -> -1.5405455 | I29: =IFERROR((E29-D29)/D29,"") -> 3.9997498 | J29: =IFERROR((F29-E29)/E29,"") -> 1.5320802 | K29: =IFERROR(F29/B29-1,"") -> -2.2348812
A30: Total equity | B30: =B28+B29 -> -3892.09 | C30: =C28+C29 -> 1419.39 | D30: =D28+D29 -> 3281.19 | E30: =E28+E29 -> 5529 | F30: =F28+F29 -> 9827.75 | G30: =IFERROR((C30-B30)/B30,"") -> -1.3646858 | H30: =IFERROR((D30-C30)/C30,"") -> 1.3116902 | I30: =IFERROR((E30-D30)/D30,"") -> 0.68505938 | J30: =IFERROR((F30-E30)/E30,"") -> 0.77749141 | K30: =IFERROR(F30/B30-1,"") -> -3.5250572
A31: Non-current borrowings | B31: ='00 Raw Data'!C44 -> 3774.69 | C31: ='00 Raw Data'!D44 -> 2008.98 | D31: ='00 Raw Data'!E44 -> 0 | E31: ='00 Raw Data'!F44 -> 0 | F31: ='00 Raw Data'!G44 -> 0 | G31: =IFERROR((C31-B31)/B31,"") -> -0.46777616 | H31: =IFERROR((D31-C31)/C31,"") -> -1 | I31: =IFERROR((E31-D31)/D31,"") | J31: =IFERROR((F31-E31)/E31,"") | K31: =IFERROR(F31/B31-1,"") -> -1
A32: Non-current lease liabilities | B32: ='00 Raw Data'!C45 -> 43.14 | C32: ='00 Raw Data'!D45 -> 4.99 | D32: ='00 Raw Data'!E45 -> 14.5 | E32: ='00 Raw Data'!F45 -> 22.97 | F32: ='00 Raw Data'!G45 -> 261.11 | G32: =IFERROR((C32-B32)/B32,"") -> -0.88433009 | H32: =IFERROR((D32-C32)/C32,"") -> 1.9058116 | I32: =IFERROR((E32-D32)/D32,"") -> 0.58413793 | J32: =IFERROR((F32-E32)/E32,"") -> 10.367436 | K32: =IFERROR(F32/B32-1,"") -> 5.0526194
A33: Other non-current financial liabilities | B33: ='00 Raw Data'!C46 -> 2351.73 | C33: ='00 Raw Data'!D46 -> 3.39 | D33: ='00 Raw Data'!E46 -> 4.58 | E33: ='00 Raw Data'!F46 -> 617.94 | F33: ='00 Raw Data'!G46 -> 628.89 | G33: =IFERROR((C33-B33)/B33,"") -> -0.99855851 | H33: =IFERROR((D33-C33)/C33,"") -> 0.35103245 | I33: =IFERROR((E33-D33)/D33,"") -> 133.9214 | J33: =IFERROR((F33-E33)/E33,"") -> 0.017720167 | K33: =IFERROR(F33/B33-1,"") -> -0.7325841
A34: Non-current provisions | B34: ='00 Raw Data'!C47 -> 112.96 | C34: ='00 Raw Data'!D47 -> 144.83 | D34: ='00 Raw Data'!E47 -> 163.41 | E34: ='00 Raw Data'!F47 -> 147.96 | F34: ='00 Raw Data'!G47 -> 207.51 | G34: =IFERROR((C34-B34)/B34,"") -> 0.28213527 | H34: =IFERROR((D34-C34)/C34,"") -> 0.12828834 | I34: =IFERROR((E34-D34)/D34,"") -> -0.094547457 | J34: =IFERROR((F34-E34)/E34,"") -> 0.40247364 | K34: =IFERROR(F34/B34-1,"") -> 0.83702195
A35: Other non-current liabilities | B35: ='00 Raw Data'!C48 -> 0.19 | C35: ='00 Raw Data'!D48 -> 0.48 | D35: ='00 Raw Data'!E48 -> 0.48 | E35: ='00 Raw Data'!F48 -> 0.45 | F35: ='00 Raw Data'!G48 -> 0.09 | G35: =IFERROR((C35-B35)/B35,"") -> 1.5263158 | H35: =IFERROR((D35-C35)/C35,"") -> 0 | I35: =IFERROR((E35-D35)/D35,"") -> -0.0625 | J35: =IFERROR((F35-E35)/E35,"") -> -0.8 | K35: =IFERROR(F35/B35-1,"") -> -0.52631579
A36: Other non-current / deferred incentives | B36: ='00 Raw Data'!C49 -> 0 | C36: ='00 Raw Data'!D49 -> 0 | D36: ='00 Raw Data'!E49 -> 0 | E36: ='00 Raw Data'!F49 -> 0 | F36: ='00 Raw Data'!G49 -> 0 | G36: =IFERROR((C36-B36)/B36,"") | H36: =IFERROR((D36-C36)/C36,"") | I36: =IFERROR((E36-D36)/D36,"") | J36: =IFERROR((F36-E36)/E36,"") | K36: =IFERROR(F36/B36-1,"")
A37: Total non-current liabilities | B37: =SUM(B31:B36) -> 6282.71 | C37: =SUM(C31:C36) -> 2162.67 | D37: =SUM(D31:D36) -> 182.97 | E37: =SUM(E31:E36) -> 789.32 | F37: =SUM(F31:F36) -> 1097.6 | G37: =IFERROR((C37-B37)/B37,"") -> -0.65577434 | H37: =IFERROR((D37-C37)/C37,"") -> -0.91539625 | I37: =IFERROR((E37-D37)/D37,"") -> 3.3139312 | J37: =IFERROR((F37-E37)/E37,"") -> 0.39056403 | K37: =IFERROR(F37/B37-1,"") -> -0.82529832
A38: Current borrowings | B38: ='00 Raw Data'!C50 -> 486.54 | C38: ='00 Raw Data'!D50 -> 323.02 | D38: ='00 Raw Data'!E50 -> 0 | E38: ='00 Raw Data'!F50 -> 0 | F38: ='00 Raw Data'!G50 -> 0 | G38: =IFERROR((C38-B38)/B38,"") -> -0.33608747 | H38: =IFERROR((D38-C38)/C38,"") -> -1 | I38: =IFERROR((E38-D38)/D38,"") | J38: =IFERROR((F38-E38)/E38,"") | K38: =IFERROR(F38/B38-1,"") -> -1
A39: Current lease liabilities | B39: ='00 Raw Data'!C51 -> 9.87 | C39: ='00 Raw Data'!D51 -> 5.21 | D39: ='00 Raw Data'!E51 -> 23.16 | E39: ='00 Raw Data'!F51 -> 12.57 | F39: ='00 Raw Data'!G51 -> 27.66 | G39: =IFERROR((C39-B39)/B39,"") -> -0.47213779 | H39: =IFERROR((D39-C39)/C39,"") -> 3.4452975 | I39: =IFERROR((E39-D39)/D39,"") -> -0.45725389 | J39: =IFERROR((F39-E39)/E39,"") -> 1.2004773 | K39: =IFERROR(F39/B39-1,"") -> 1.8024316
A40: Trade payables – MSME | B40: ='00 Raw Data'!C52 -> 58.98 | C40: ='00 Raw Data'!D52 -> 2.7 | D40: ='00 Raw Data'!E52 -> 33.92 | E40: ='00 Raw Data'!F52 -> 61.86 | F40: ='00 Raw Data'!G52 -> 124.48 | G40: =IFERROR((C40-B40)/B40,"") -> -0.95422177 | H40: =IFERROR((D40-C40)/C40,"") -> 11.562963 | I40: =IFERROR((E40-D40)/D40,"") -> 0.82370283 | J40: =IFERROR((F40-E40)/E40,"") -> 1.0122858 | K40: =IFERROR(F40/B40-1,"") -> 1.1105459
A41: Trade payables – others | B41: ='00 Raw Data'!C53 -> 1756.96 | C41: ='00 Raw Data'!D53 -> 1059.39 | D41: ='00 Raw Data'!E53 -> 2148.06 | E41: ='00 Raw Data'!F53 -> 3271.34 | F41: ='00 Raw Data'!G53 -> 4385.84 | G41: =IFERROR((C41-B41)/B41,"") -> -0.39703237 | H41: =IFERROR((D41-C41)/C41,"") -> 1.0276385 | I41: =IFERROR((E41-D41)/D41,"") -> 0.52292766 | J41: =IFERROR((F41-E41)/E41,"") -> 0.34068608 | K41: =IFERROR(F41/B41-1,"") -> 1.4962663
...

Sheet 04 Balance Ratios
A1: 04. Balance Sheet Ratios – Suzlon Energy Limited
A2: Formula-driven ratios using the audited standalone balance sheet.
A4: Ratio | B4: FY22 | C4: FY23 | D4: FY24 | E4: FY25 | F4: FY26 | G4: 5-Year Trend | H4: Interpretation / Analysis
A5: Current ratio | B5: =IFERROR('03 Balance Sheet'!B26/'03 Balance Sheet'!B47,"") -> 0.87664402 | C5: =IFERROR('03 Balance Sheet'!C26/'03 Balance Sheet'!C47,"") -> 0.83712839 | D5: =IFERROR('03 Balance Sheet'!D26/'03 Balance Sheet'!D47,"") -> 1.4171928 | E5: =IFERROR('03 Balance Sheet'!E26/'03 Balance Sheet'!E47,"") -> 1.3866306 | F5: =IFERROR('03 Balance Sheet'!F26/'03 Balance Sheet'!F47,"") -> 1.5954622 | G5: Liquidity strengthened as cash, receivables and working capital expanded, but FY26 current liabilities also rose. | H5: Liquidity strengthened as cash, receivables and working capital expanded, but FY26 current liabilities also rose.
A6: Quick ratio | B6: =IFERROR(('03 Balance Sheet'!B26-'03 Balance Sheet'!B17)/'03 Balance Sheet'!B47,"") -> 0.52121085 | C6: =IFERROR(('03 Balance Sheet'!C26-'03 Balance Sheet'!C17)/'03 Balance Sheet'!C47,"") -> 0.52875791 | D6: =IFERROR(('03 Balance Sheet'!D26-'03 Balance Sheet'!D17)/'03 Balance Sheet'!D47,"") -> 0.79357039 | E6: =IFERROR(('03 Balance Sheet'!E26-'03 Balance Sheet'!E17)/'03 Balance Sheet'!E47,"") -> 0.91251116 | F6: =IFERROR(('03 Balance Sheet'!F26-'03 Balance Sheet'!F17)/'03 Balance Sheet'!F47,"") -> 1.0985665 | G6: Quick liquidity improved from a very weak base in FY22; still monitor working-capital intensity. | H6: Quick liquidity improved from a very weak base in FY22; still monitor working-capital intensity.
A7: Cash ratio | B7: =IFERROR(('03 Balance Sheet'!B20+'03 Balance Sheet'!B21)/'03 Balance Sheet'!B47,"") -> 0.12482951 | C7: =IFERROR(('03 Balance Sheet'!C20+'03 Balance Sheet'!C21)/'03 Balance Sheet'!C47,"") -> 0.11785817 | D7: =IFERROR(('03 Balance Sheet'!D20+'03 Balance Sheet'!D21)/'03 Balance Sheet'!D47,"") -> 0.10998242 | E7: =IFERROR(('03 Balance Sheet'!E20+'03 Balance Sheet'!E21)/'03 Balance Sheet'!E47,"") -> 0.16541269 | F7: =IFERROR(('03 Balance Sheet'!F20+'03 Balance Sheet'!F21)/'03 Balance Sheet'!F47,"") -> 0.1219287 | G7: Cash-plus-bank liquidity is substantially stronger than FY22 despite FY26 lease/current obligations. | H7: Cash-plus-bank liquidity is substantially stronger than FY22 despite FY26 lease/current obligations.
A8: Debt-to-equity | B8: =IFERROR(('03 Balance Sheet'!B31+'03 Balance Sheet'!B38)/'03 Balance Sheet'!B30,"") -> -1.0948436 | C8: =IFERROR(('03 Balance Sheet'!C31+'03 Balance Sheet'!C38)/'03 Balance Sheet'!C30,"") -> 1.6429593 | D8: =IFERROR(('03 Balance Sheet'!D31+'03 Balance Sheet'!D38)/'03 Balance Sheet'!D30,"") -> 0 | E8: =IFERROR(('03 Balance Sheet'!E31+'03 Balance Sheet'!E38)/'03 Balance Sheet'!E30,"") -> 0 | F8: =IFERROR(('03 Balance Sheet'!F31+'03 Balance Sheet'!F38)/'03 Balance Sheet'!F30,"") -> 0 | G8: Debt-to-equity fell sharply after FY23 and remains low because equity turned strongly positive. | H8: Debt-to-equity fell sharply after FY23 and remains low because equity turned strongly positive.
A9: Lease liabilities / Equity | B9: =IFERROR(('03 Balance Sheet'!B32+'03 Balance Sheet'!B39)/'03 Balance Sheet'!B30,"") -> -0.013619932 | C9: =IFERROR(('03 Balance Sheet'!C32+'03 Balance Sheet'!C39)/'03 Balance Sheet'!C30,"") -> 0.0071861856 | D9: =IFERROR(('03 Balance Sheet'!D32+'03 Balance Sheet'!D39)/'03 Balance Sheet'!D30,"") -> 0.011477543 | E9: =IFERROR(('03 Balance Sheet'!E32+'03 Balance Sheet'!E39)/'03 Balance Sheet'!E30,"") -> 0.0064279255 | F9: =IFERROR(('03 Balance Sheet'!F32+'03 Balance Sheet'!F39)/'03 Balance Sheet'!F30,"") -> 0.029383124 | G9: Lease burden is rising again in FY26, driven by business expansion and right-of-use assets. | H9: Lease burden is rising again in FY26, driven by business expansion and right-of-use assets.
A10: Total liabilities / Assets | B10: =IFERROR(('03 Balance Sheet'!B37+'03 Balance Sheet'!B47)/'03 Balance Sheet'!B27,"") -> 1.6857994 | C10: =IFERROR(('03 Balance Sheet'!C37+'03 Balance Sheet'!C47)/'03 Balance Sheet'!C27,"") -> 0.76531211 | D10: =IFERROR(('03 Balance Sheet'!D37+'03 Balance Sheet'!D47)/'03 Balance Sheet'!D27,"") -> 0.51440495 | E10: =IFERROR(('03 Balance Sheet'!E37+'03 Balance Sheet'!E47)/'03 Balance Sheet'!E27,"") -> 0.55210678 | F10: =IFERROR(('03 Balance Sheet'!F37+'03 Balance Sheet'!F47)/'03 Balance Sheet'!F27,"") -> 0.45657343 | G10: Liability intensity fell materially as equity rebuilt, although FY26 lease/current liabilities increased. | H10: Liability intensity fell materially as equity rebuilt, although FY26 lease/current liabilities increased.
A11: Equity ratio | B11: =IFERROR('03 Balance Sheet'!B30/'03 Balance Sheet'!B27,"") -> -0.68579942 | C11: =IFERROR('03 Balance Sheet'!C30/'03 Balance Sheet'!C27,"") -> 0.23468789 | D11: =IFERROR('03 Balance Sheet'!D30/'03 Balance Sheet'!D27,"") -> 0.48559505 | E11: =IFERROR('03 Balance Sheet'!E30/'03 Balance Sheet'!E27,"") -> 0.44789322 | F11: =IFERROR('03 Balance Sheet'!F30/'03 Balance Sheet'!F27,"") -> 0.54342657 | G11: Equity ratio moved from negative in FY22 to above 50% by FY26. | H11: Equity ratio moved from negative in FY22 to above 50% by FY26.
A12: Receivables / Revenue | B12: =IFERROR('03 Balance Sheet'!B19/'01 Income Statement'!B5,"") -> 0.16793991 | C12: =IFERROR('03 Balance Sheet'!C19/'01 Income Statement'!C5,"") -> 0.15440881 | D12: =IFERROR('03 Balance Sheet'!D19/'01 Income Statement'!D5,"") -> 0.28427503 | E12: =IFERROR('03 Balance Sheet'!E19/'01 Income Statement'!E5,"") -> 0.36243308 | F12: =IFERROR('03 Balance Sheet'!F19/'01 Income Statement'!F5,"") -> 0.38143418 | G12: Receivables increased with scale; FY26 receivables are significant and deserve collection monitoring. | H12: Receivables increased with scale; FY26 receivables are significant and deserve collection monitoring.
A13: Inventory / Revenue | B13: =IFERROR('03 Balance Sheet'!B17/'01 Income Statement'!B5,"") -> 0.29367285 | C13: =IFERROR('03 Balance Sheet'!C17/'01 Income Statement'!C5,"") -> 0.21492083 | D13: =IFERROR('03 Balance Sheet'!D17/'01 Income Statement'!D5,"") -> 0.35197066 | E13: =IFERROR('03 Balance Sheet'!E17/'01 Income Statement'!E5,"") -> 0.28116734 | F13: =IFERROR('03 Balance Sheet'!F17/'01 Income Statement'!F5,"") -> 0.23632186 | G13: Inventory grew with the business; working-capital discipline remains important. | H13: Inventory grew with the business; working-capital discipline remains important.
A14: Working capital (₹ Crore) | B14: ='03 Balance Sheet'!B26-'03 Balance Sheet'!B47 -> -405.18 | C14: ='03 Balance Sheet'!C26-'03 Balance Sheet'!C47 -> -401.63 | D14: ='03 Balance Sheet'!D26-'03 Balance Sheet'!D47 -> 1373.77 | E14: ='03 Balance Sheet'!E26-'03 Balance Sheet'!E47 -> 2329.89 | F14: ='03 Balance Sheet'!F26-'03 Balance Sheet'!F47 -> 4263.17 | G14: Working capital turned strongly positive and expanded in FY25–FY26. | H14: Working capital turned strongly positive and expanded in FY25–FY26.
A15: Working capital / Revenue | B15: =IFERROR(('03 Balance Sheet'!B26-'03 Balance Sheet'!B47)/'01 Income Statement'!B5,"") -> -0.10192156 | C15: =IFERROR(('03 Balance Sheet'!C26-'03 Balance Sheet'!C47)/'01 Income Statement'!C5,"") -> -0.11351445 | D15: =IFERROR(('03 Balance Sheet'!D26-'03 Balance Sheet'!D47)/'01 Income Statement'!D5,"") -> 0.23546239 | E15: =IFERROR(('03 Balance Sheet'!E26-'03 Balance Sheet'!E47)/'01 Income Statement'!E5,"") -> 0.22928377 | F15: =IFERROR(('03 Balance Sheet'!F26-'03 Balance Sheet'!F47)/'01 Income Statement'!F5,"") -> 0.28319974 | G15: Working capital as a share of revenue remains positive and supports growth, but ties up capital. | H15: Working capital as a share of revenue remains positive and supports growth, but ties up capital.

Sheet 05 Red Flags
A1: 05. Five-Year Red Flag Analysis – Suzlon Energy Limited
A2: Assessment combines audited financial statements, notes, BRSR and MD&A. Severity is analytical, not an audit conclusion.
A4: Red Flag / Risk Area | B4: FY22 | C4: FY23 | D4: FY24 | E4: FY25 | F4: FY26 | G4: Severity
A5: Revenue quality | B5: High | C5: Low | D5: Low | E5: Low | F5: Low | G5: Medium
A6: Margin compression | B6: High | C6: Medium | D6: Low | E6: Low | F6: Low | G6: Low
A7: Other-income dependence | B7: Low | C7: Low | D7: Low | E7: Low | F7: Low | G7: Low
A8: Exceptional items | B8: High | C8: High | D8: Medium | E8: Medium | F8: High | G8: High
A9: Tax anomaly | B9: Low | C9: Low | D9: Low | E9: High | F9: High | G9: High
A10: Interest coverage | B10: High | C10: Medium | D10: Medium | E10: Low | F10: Low | G10: Medium
A11: Debt / lease burden | B11: High | C11: High | D11: Medium | E11: Medium | F11: High | G11: Medium
A12: Receivables build-up | B12: Medium | C12: Low | D12: Medium | E12: Medium | F12: Medium | G12: Medium
A13: Inventory build-up | B13: Medium | C13: Low | D13: Medium | E13: Medium | F13: Medium | G13: Medium
A14: Liquidity stress | B14: High | C14: High | D14: Medium | E14: Low | F14: Low | G14: Medium
A15: Weak equity | B15: High | C15: High | D15: Medium | E15: Low | F15: Low | G15: High
... A24: Other | B24: Medium | C24: High | D24: High | E24: Medium | F24: High | G24: High

Sheet 06 ESG
A1: 06. Five-Year ESG Analysis – Suzlon Energy Limited
A2: ESG metrics are taken from the BRSR/sustainability disclosures. Where a metric was not disclosed on a comparable basis, 'NR / not comparable' is used rather than inventing a number.
A4: Pillar | B4: Metric / Theme | C4: FY22 | D4: FY23 | E4: FY24 | F4: FY25 | G4: FY26 | H4: 5-Year Trend
A5: E | B5: Total energy consumption | C5: 3068883.6 | D5: 4668645.6 | E5: 293268.44 | F5: 410930.69 | G5: 452133.76 | H5: Reporting boundary/methodology changed materially after FY23; do not interpret the fall in FY24 as pure efficiency.
A6: E | B6: Renewable energy consumption | C6: 38523.37 | D6: 19354.9 | E6: 17830 | F6: 92428.3 | G6: 113500.39 | H6: Renewable energy use rose strongly in FY25–FY26.
A7: E | B7: Scope 1 emissions | C7: 7944 | D7: 6183 | E7: 5969 | F7: 9002 | G7: 6835 | H7: Scope 1 reduced 24.1% in FY26 vs FY25.
A8: E | B8: Scope 2 emissions | D8: 27885 | E8: 40264 | F8: 39924 | G8: 49564 | H8: FY22 not separately comparable in the later BRSR presentation.
A9: E | B9: Scope 3 emissions | D9: 9875338 | E9: 18182 | F9: 795453 | G9: 1287876 | H9: Major methodology/boundary change; FY23–FY26 figures are not directly comparable without category-level review.
A10: E | B10: Scope 1+2 intensity | D10: 4.59 | E10: 6.96e-07 | F10: 4.5e-07 | G10: 3.2e-07 | H10: Intensity improved sharply under the reported methodology.
A11: E | B11: Water withdrawal | C11: 223936.97 | D11: 178180.72 | E11: 309180 | F11: 255838.74 | G11: 344324 | H11: Withdrawal rose in FY26; water-stress and water-positivity initiatives remain relevant.
A12: E | B12: Water consumption | C12: 223936.97 | D12: 178180.72 | F12: 205395.68 | G12: 342525 | H12: FY24 consumption is not used here because the reported basis is not fully comparable.
A13: E | B13: Waste / Zero Waste to Landfill | C13: NR | D13: NR | E13: NR | F13: 90.14% achieved | G13: Progress toward 100% ZWTL by 2028 | H13: Circularity and waste diversion improved; FY25 reported 90.14% ZWTL.
A14: E | B14: Climate / net-zero target | C14: NR | D14: NR | E14: Net Zero Scope 1&2 by 2035 | F14: Net Zero Scope 1&2 by 2035; Scope 3 by 2040 | G14: Net Zero Scope 1&2 by 2035; Scope 3 by 2040 | H14: Targets became more explicit and measurable.
A15: E | B15: Biodiversity | C15: NR / qualitative | D15: Qualitative | E15: Qualitative | F15: Qualitative | G15: Qualitative | H15: Renewable projects and lifecycle impacts are discussed; no single comparable five-year KPI.
A16: S | B16: Permanent employees | C16: 1592 | D16: 1451 | E16: 1528 | F16: 1680 | G16: 5603 | H16: FY26 increase reflects the SGSL amalgamation; not pure organic hiring.
A17: S | B17: Women employees | C17: NR | D17: NR / qualitative | E17: Target 10% by 2030 | F17: 231% growth over three years | G17: 6.52% of employees; +72.61% YoY | H17: Gender representation is improving but remains below 10% 2030 target.
A18: S | B18: Employee turnover | C18: N | D18: R | H18: Reported in BRSR
A19: S | B19: Training | C19: NR | D19: BRSR training disclosures | E19: BRSR training disclosures | F19: Skill development / ESG training | G19: 100% employees provided skill-upgradation training | H19: Training coverage strengthened.
A20: S | B20: Health & safety | C20: FY22 LTIFR disclosed in BRSR | D20: Employee LTIFR 0.94; worker LTIFR 0.54 (FY23 table) | E20: Employee LTIFR 0.27; worker LTIFR disclosed | F20: BRSR safety indicators | G20: Safety systems strengthened; FY26 ESG highlights include 100% training/controls | H20: Safety reporting is improving but incidents require context by employee/worker category.
A21: S | B21: Wellbeing | C21: Qualitative | D21: Qualitative | E21: Qualitative | F21: DEIB / wellbeing | G21: Wellbeing measures and return-to-work programmes | H21: Qualitative improvement.
A22: S | B22: CSR / community | C22: CSR/community programmes | D22: CSR/community programmes | E22: CSR/community programmes | F22: Community clean-power and rural initiatives | G22: SROI of ₹39.22 per ₹1 invested reported for need-based CSR interventions | H22: Increasing measurement of social return.
A23: S | B23: Human rights / supply chain | C23: Supplier screening | D23: 100% Class A suppliers sustainably sourced | E23: Human-rights target set | F23: Supplier Code / ESG assessments | G23: Human Rights Due Diligence across operations | H23: Governance of value chain strengthened.

Sheet 07 MD&A
A1: 07. Five-Year MD&A Analysis – Suzlon Energy Limited
A2: Captures the key discussion points from the five annual reports, with emphasis on drivers, risks, strategy, cash flow, ESG and outlook.
A4: MD&A Area | B4: FY22 | C4: FY23 | D4: FY24 | E4: FY25 | F4: FY26 | G4: 5-Year Change / Trend | H4: Interpretation
A5: Business overview | B5: Wind turbine equipment + OMS; restructuring-driven recovery | C5: WTG, OMS and Foundry/Forge; 20 GW installed milestone | D5: Wind demand recovery; manufacturing and OMS scale | E5: Strong WTG growth; Renom acquisition and SGSL merger process | F5: Strong WTG/OMS scale; SGSL merger effective; project-division transfers | G5: Business shifted from restructuring/recovery to scale-led growth | H5: Core wind business is now the main growth engine, with OMS providing recurring revenue.
A6: Industry & macro environment | B6: Post-COVID recovery; commodity/logistics inflation | C6: Renewables policy support; strong wind opportunity | D6: India wind capacity additions and policy support improved | E6: Wind tendering, domestic manufacturing and grid/renewable demand supportive | F6: India renewable build-out, transmission and wind demand remain strong | G6: Industry tailwinds strengthened | H6: Macro/policy support is a major positive, while execution and supply-chain risks remain.
A7: Revenue drivers | B7: Volumes pickup post restructuring | C7: WTG and OMS; revenue ₹3,538 Cr | D7: Restated revenue ₹5,834 Cr | E7: Revenue ₹10,162 Cr | F7: Revenue ₹15,054 Cr | G7: ~3.8x FY22 revenue | H7: Growth is increasingly volume/order-execution driven rather than restructuring-only.
A8: Cost drivers | B8: Commodity/logistics inflation; finance costs high | C8: Raw material and finance costs weighed on margins | D8: Cost intensity improved | E8: Scale increased; raw material cost rose with volumes | F8: Raw material and other expenses rose with scale; finance cost also increased | G8: Margins expanded despite higher absolute costs | H8: Operating leverage is visible, but FY26 cost growth and finance cost require monitoring.
A9: Operating performance | B9: EBITDA ~₹132 Cr; EBIT negative | C9: EBITDA ₹252 Cr; exceptional gain drove PAT | D9: EBITDA ~₹958 Cr on restated basis | E9: EBITDA ₹1,664 Cr | F9: EBITDA ₹2,822 Cr | G9: Major operating turnaround | H9: Underlying operations improved far more steadily than reported PAT because exceptional items distorted earnings.
A10: Liquidity & capital resources | B10: Negative equity; borrowings high | C10: Negative equity improved; debt still significant | D10: Equity turned positive; borrowings reduced | E10: Strong positive equity; borrowings largely eliminated | F10: Positive equity ₹9,828 Cr; lease liabilities rose | G10: Capital structure strengthened materially | H10: Balance-sheet repair is one of the clearest five-year improvements.
A11: Capital expenditure | B11: Controlled after restructuring | C11: Selective capex; R&D focus | D11: Capex to support future demand | E11: Manufacturing/R&D expansion and product development | F11: CWIP/PPE/ROU expanded to support growth | G11: Growth capex intensified | H11: Capex is growth-oriented; returns depend on order execution and capacity utilisation.
A12: Cash flow | B12: ₹1,302 Cr consolidated operating cash flow; debt repayments | C12: Positive operating cash flow; financing restructuring | D12: Positive operating cash flow; capex outflow | E12: Improved operating cash generation | F12: Cash and bank balances expanded, with higher working capital needs | G12: Cash-generation capacity improved | H12: Working-capital discipline becomes more important as receivables/inventory scale.
A13: Risk factors | B13: Commodity, FX, policy, debt/restructuring | C13: Execution, FX, policy and commodity risks | D13: Demand, execution and policy risks | E13: Supply chain, competition, FX, policy and execution | F13: Demand, policy, FX, competition, restructuring and execution | G13: Risk profile shifted from solvency toward execution/growth | H13: Financial risk has reduced, but operating and execution risk is more important.
A14: Strategic priorities | B14: Restructure and stabilise | C14: Strengthen WTG/OMS and technology | D14: Scale India wind opportunity | E14: Renom/OMS, product innovation, ESG and capacity | F14: Scale WTG/OMS, integrate acquisitions, improve circularity and ESG | G14: Strategy became growth + ESG focused | H14: Suzlon moved from turnaround strategy to expansion and operational excellence.
A15: Human capital | B15: 1,592 permanent employees | C15: 1,451 | D15: 1,528 | E15: 1,680 | F15: 5,603 after SGSL amalgamation | G15: Large FY26 step-up mainly due merger | H15: Workforce data must be interpreted with structural changes in the group.
... A21: Other material MD&A point | B21: Restructuring and debt reduction | C21: 20 GW milestone; exceptional gain | D21: QIP/rights issue and restatement later affected comparability | E21: Renom and SGSL; project division restructuring | F21: SGSL merger and project-division transfers effective | G21: Structural transactions complicate year-on-year comparability | H21: Always reconcile MD&A with Notes to Accounts before concluding on trends.

Sheet 08 Sources & Notes
A1: 08. SOURCES, BASIS & IMPORTANT NOTES
A3: Company | B3: Suzlon Energy Limited
A4: Analysis period | B4: FY2021-22 to FY2025-26
A5: Financial statement basis | B5: Standalone audited Ind AS financial statements
A7: Annual Report | B7: Official Suzlon FY2021-22 Annual Report | C7: https://www.suzlon.com/pdf/investor/financial-reports-presentations/2021-22/fourth-quarter/Annual_Report-FY22-2021-2022.pdf
A8: Annual Report | B8: Official Suzlon FY2022-23 Annual Report | C8: https://www.suzlon.com/pdf/investor/financial-reports-presentations/2022-23/fourth-quarter/Annual_Report_22-23.pdf
A9: Annual Report | B9: Official Suzlon FY2023-24 Annual Report | C9: https://www.suzlon.com/pdf/investor/financial-reports-presentations/2023-24/fourth-quarter/Annual_Report_2023-20241.pdf
A10: Annual Report | B10: Official Suzlon FY2024-25 Annual Report | C10: https://www.suzlon.com/pdf/investor/financial-reports-presentations/2024-25/fourth-quarter/Annual_Report_2024-25.pdf
A11: Annual Report | B11: Official Suzlon FY2025-26 Annual Report | C11: https://www.suzlon.com/pdf/investor/financial-reports-presentations/2025-26/fourth-quarter/Annual-Report.pdf
A13: Key audit / accounting note | B13: FY24 was restated in the FY25 report under Ind AS 103. Do not mix FY24 numbers from the FY24 standalone statement with the restated FY24 comparative used here.
A14: Key red flag | B14: Exceptional items and deferred-tax credits materially affect reported PAT; operating EBITDA/EBIT are more useful for underlying performance.
A15: Key ESG note | B15: Scope 3 and energy/water metrics have reporting-boundary or methodology changes across years; compare only after reading the BRSR definitions.
A16: Key structural note | B16: FY26 workforce and balance-sheet changes are affected by the SGSL amalgamation and project-division transfers.
A18: **AI Collaboration Disclaimer:** AI tools were used as a collaborators to assist with spreadsheet structure, formula checking, interpretation of financial trends, and identification of key discussion points. Financial figures were taken and cross-checked from Suzlon Energy Limited's audited Annual Reports.
